Workbook

Sheet turkey_rental_multiplier
A1: FB010 | B1: cpi_rent | C1: cpi_rent_growth | D1: cpi_2003_100 | E1: inflation | F1: house_price_index_2023100 | G1: house_price_growth | H1: sahibinden_rental_turkiye | I1: sahibinden_kondeger_turkiye | J1: hba_rental_val_original | K1: price_to_rent_sahibinden2 | L1: silc_mean_imputed_rent | M1: imprent_correction | N1: imprent_upgrade_factor
A2: 2003 | B2: 100 | C2: =(B3-B2)/B2 -> 0.4132 | D2: 100 | E2: =(D3-D2)/D2 -> 0.14485579
A3: 2005 | B3: =cpi_june!E2 -> 141.32 | C3: =(B4-B3)/B3 -> 0.20209454 | D3: 114.48558 | E3: =(D4-D3)/D3 -> 0.079349911 | G3: =(J4-J3)/J3 -> 0.38559669 | H3: =H4/(1+C3) -> 299.41989 | I3: =I4/(1+G3) -> 43985.333 | J3: 32667.76 | K3: =I3/H3 -> 146.90184 | N3: =AVERAGE(M5:M20) -> 2.6537759
A4: 2006 | B4: =cpi_june!E3 -> 169.88 | C4: =(B5-B4)/B4 -> 0.19443136 | D4: 123.57 | E4: =(D5-D4)/D4 -> 0.099295946 | G4: =(J5-J4)/J4 -> 0.1387547 | H4: =H5/(1+C4) -> 359.93102 | I4: =I5/(1+G4) -> 60945.931 | J4: 45264.34 | K4: =I4/H4 -> 169.3267 | N4: =N3 -> 2.6537759
A5: 2007 | B5: =cpi_june!E4 -> 202.91 | C5: =(B6-B5)/B5 -> 0.14070277 | D5: 135.84 | E5: =(D6-D5)/D5 -> 0.081713781 | G5: =(J6-J5)/J5 -> 0.19879298 | H5: =H6/(1+C5) -> 429.9129 | I5: =I6/(1+G5) -> 69402.466 | J5: 51544.98 | K5: =I5/H5 -> 161.43378 | L5: 1933.1638 | M5: =((H5*12)/L5) -> 2.6686589 | N5: =N3 -> 2.6537759
A6: 2008 | B6: =cpi_june!E5 -> 231.46 | C6: =(B7-B6)/B6 -> 0.087358507 | D6: 146.94 | E6: =(D7-D6)/D6 -> 0.095004764 | G6: =(J7-J6)/J6 -> -0.047355505 | H6: =H7/(1+C6) -> 490.40284 | I6: =I7/(1+G6) -> 83199.188 | J6: 61791.76 | K6: =I6/H6 -> 169.65479 | L6: 2189.0355 | M6: =((H6*12)/L6) -> 2.6883228 | N6: =N5 -> 2.6537759
A7: 2009 | B7: =cpi_june!E6 -> 251.68 | C7: =(B8-B7)/B7 -> 0.042116974 | D7: 160.9 | E7: =(D8-D7)/D7 -> 0.081852082 | G7: =(J8-J7)/J7 -> 0.067783924 | H7: =H8/(1+C7) -> 533.2437 | I7: =I8/(1+G7) -> 79259.249 | J7: 58865.58 | K7: =I7/H7 -> 148.63607 | L7: 2470.1196 | M7: =((H7*12)/L7) -> 2.5905322 | N7: =N6 -> 2.6537759
A8: 2010 | B8: =cpi_june!E7 -> 262.28 | C8: =(B9-B8)/B8 -> 0.04426567 | D8: 174.07 | E8: =(D9-D8)/D8 -> 0.049003275 | G8: =(J9-J8)/J8 -> 0.16124976 | H8: =H9/(1+C8) -> 555.70231 | I8: =I9/(1+G8) -> 84631.752 | J8: 62855.72 | K8: =I8/H8 -> 152.29692 | L8: 2687.2122 | M8: =((H8*12)/L8) -> 2.4815411 | N8: =N7 -> 2.6537759
A9: 2011 | B9: =cpi_june!E8 -> 273.89 | C9: =(B10-B9)/B9 -> 0.048048487 | D9: 182.6 | E9: =(D10-D9)/D9 -> 0.10613363 | G9: =(J10-J9)/J9 -> 0.15173872 | H9: =H10/(1+C9) -> 580.30084 | I9: =I10/(1+G9) -> 98278.602 | J9: 72991.19 | K9: =I9/H9 -> 169.35802 | L9: 2715.1743 | M9: =((H9*12)/L9) -> 2.564701 | N9: =N8 -> 2.6537759
A10: 2012 | B10: =cpi_june!E9 -> 287.05 | C10: =(B11-B10)/B10 -> 0.061661731 | D10: 201.98 | E10: =(D11-D10)/D10 -> 0.073076542 | F10: =house_price_index_evds!C9 -> 5.67 | G10: =(F11-F10)/F10 -> 0.11287478 | H10: =H11/(1+C10) -> 608.18342 | I10: =I11/(1+G10) -> 113191.27 | J10: 84066.78 | K10: =I10/H10 -> 186.11371 | L10: 2644.7564 | M10: =((H10*12)/L10) -> 2.7594984 | N10: =N9 -> 2.6537759
A11: 2013 | B11: =cpi_june!E10 -> 304.75 | C11: =(B12-B11)/B11 -> 0.06802297 | D11: 216.74 | E11: =(D12-D11)/D11 -> 0.077512227 | F11: =house_price_index_evds!C10 -> 6.31 | G11: =(F12-F11)/F11 -> 0.1251981 | H11: =H12/(1+C11) -> 645.68506 | I11: =I12/(1+G11) -> 125967.71 | J11: 87101.62 | K11: =I11/H11 -> 195.09157 | L11: 2733.4253 | M11: =((H11*12)/L11) -> 2.8346195 | N11: =N10 -> 2.6537759
A12: 2014 | B12: =cpi_june!E11 -> 325.48 | C12: =(B13-B12)/B12 -> 0.074658965 | D12: 233.54 | E12: =(D13-D12)/D12 -> 0.072407296 | F12: =house_price_index_evds!C11 -> 7.1 | G12: =(F13-F12)/F12 -> 0.15774648 | H12: =H13/(1+C12) -> 689.60648 | I12: =I13/(1+G12) -> 141738.63 | J12: 106254.9 | K12: =I12/H12 -> 205.53552 | L12: 3179.6084 | M12: =((H12*12)/L12) -> 2.6026091 | N12: =N11 -> 2.6537759
A13: 2015 | B13: =cpi_june!E12 -> 349.78 | C13: =(B14-B13)/B13 -> 0.088284064 | D13: 250.45 | E13: =(D14-D13)/D13 -> 0.095787582 | F13: =house_price_index_evds!C12 -> 8.22 | G13: =(F14-F13)/F13 -> 0.12773723 | H13: =H14/(1+C13) -> 741.09178 | I13: =I14/(1+G13) -> 164097.4 | J13: =J12*(1+G12) -> 123016.24 | K13: =I13/H13 -> 221.42655 | L13: 3467.6421 | M13: =((H13*12)/L13) -> 2.5645961 | N13: =N12 -> 2.6537759
A14: 2016 | B14: =cpi_june!E13 -> 380.66 | C14: =(B15-B14)/B14 -> 0.088110125 | D14: 274.44 | E14: =(D15-D14)/D14 -> 0.092187728 | F14: =house_price_index_evds!C13 -> 9.27 | G14: =(F15-F14)/F14 -> 0.10895361 | H14: =H15/(1+C14) -> 806.51838 | I14: =I15/(1+G14) -> 185058.75 | J14: =J13*(1+G13) -> 138729.99 | K14: =I14/H14 -> 229.45385 | L14: 3261.4627 | M14: =((H14*12)/L14) -> 2.9674478 | N14: =N13 -> 2.6537759
A15: 2017 | B15: =cpi_june!E14 -> 414.2 | C15: =(B16-B15)/B15 -> 0.096185418 | D15: 299.74 | E15: =(D16-D15)/D15 -> 0.10345633 | F15: =house_price_index_evds!C14 -> 10.28 | G15: =(F16-F15)/F15 -> 0.077821012 | H15: =H16/(1+C15) -> 877.58081 | I15: =I16/(1+G15) -> 205221.56 | J15: =J14*(1+G14) -> 153845.12 | K15: =I15/H15 -> 233.84919 | L15: 3643.9959 | M15: =((H15*12)/L15) -> 2.889951 | N15: =N14 -> 2.6537759
A16: 2018 | B16: =cpi_june!E15 -> 454.04 | C16: =(B17-B16)/B16 -> 0.10201744 | D16: 330.75 | E16: =(D17-D16)/D16 -> 0.20353741 | F16: =house_price_index_evds!C15 -> 11.08 | G16: =(F17-F16)/F16 -> 0.047833935 | H16: =H17/(1+C16) -> 961.99129 | I16: =I17/(1+G16) -> 221192.11 | J16: =J15*(1+G15) -> 165817.51 | K16: =I16/H16 -> 229.93151 | L16: 4555.434 | M16: =((H16*12)/L16) -> 2.5340935 | N16: =N15 -> 2.6537759
A17: 2019 | B17: =cpi_june!E16 -> 500.36 | C17: =(B18-B17)/B17 -> 0.092193621 | D17: 398.07 | E17: =(D18-D17)/D17 -> 0.12153641 | F17: =house_price_index_evds!C16 -> 11.61 | G17: =(F18-F17)/F17 -> 0.23858742 | H17: =H18/(1+C17) -> 1060.1312 | I17: =I18/(1+G17) -> 231772.6 | J17: =J16*(1+G16) -> 173749.21 | K17: =I17/H17 -> 218.62634 | L17: 5267.3189 | M17: =((H17*12)/L17) -> 2.4151897 | N17: =N16 -> 2.6537759
A18: 2020 | B18: =cpi_june!E17 -> 546.49 | C18: =(B19-B18)/B18 -> 0.09934308 | D18: 446.45 | E18: =(D19-D18)/D18 -> 0.14973681 | F18: =house_price_index_evds!C17 -> 14.38 | G18: =(F19-F18)/F18 -> 0.37482615 | H18: =H19/(1+C18) -> 1157.8685 | I18: =I19/(1+G18) -> 287070.63 | J18: =J17*(1+G17) -> 215203.59 | K18: =I18/H18 -> 247.93025 | L18: 6054.6882 | M18: =((H18*12)/L18) -> 2.2948204 | N18: =N17 -> 2.6537759
A19: 2021 | B19: =cpi_june!E18 -> 600.78 | C19: =(B20-B19)/B19 -> 0.22798695 | D19: 513.3 | E19: =(D20-D19)/D19 -> 0.48690824 | F19: =house_price_index_evds!C18 -> 19.77 | G19: =(F20-F19)/F19 -> 1.4997471 | H19: =AVERAGE(sahibinden_rent_and_price_june!D2:D77) -> 1272.8947 | I19: =AVERAGE(sahibinden_rent_and_price_june!E2:E77) -> 394672.21 | J19: =J18*(1+G18) -> 295867.52 | K19: =I19/H19 -> 310.0588 | L19: 5524.0546 | M19: =((H19*12)/L19) -> 2.7651314 | N19: =N18 -> 2.6537759
A20: 2022 | B20: =cpi_june!E19 -> 737.75 | C20: =(B21-B20)/B20 -> 0.75905117 | D20: 763.23 | E20: =(D21-D20)/D20 -> -1 | F20: =house_price_index_evds!C19 -> 49.42 | G20: =(F21-F20)/F20 -> 1.0234723 | H20: =AVERAGE(sahibinden_rent_and_price_june!D78:D154) -> 3048.5584 | I20: =AVERAGE(sahibinden_rent_and_price_june!E78:E154) -> 1037824.9 | J20: =J19*(1+G19) -> 739593.97 | K20: =I20/H20 -> 340.43136 | L20: 12887.129 | M20: =((H20*12)/L20) -> 2.8387007 | N20: =N19 -> 2.6537759
A21: 2023 | B21: =cpi_june!E20 -> 1297.74 | F21: =house_price_index_evds!C20 -> 100

Sheet regional_rent_multiplier_ibbs1
A1: year | B1: TR1 | C1: TR2 | D1: TR2 | E1: TR3 | F1: TR3 | G1: TR3 | H1: TR4 | I1: TR4 | J1: TR5 | K1: TR5 | L1: TR6 | M1: TR6 | N1: TR6 | O1: TR7 | P1: TR7 | Q1: TR8 | R1: TR8 | S1: TR8 | T1: TR9 | U1: TRA | V1: TRA | W1: TRB | X1: TRB | Y1: TRC | Z1: TRC | AA1: TRC
A2: 2005 | B2: =regional_houseprice!B2/regional_rent!B2 -> 72.344727 | C2: =regional_houseprice!C2/regional_rent!C2 -> 141.27845 | D2: =regional_houseprice!D2/regional_rent!D2 -> 171.28356 | E2: =regional_houseprice!E2/regional_rent!E2 -> 101.86069 | F2: =regional_houseprice!F2/regional_rent!F2 -> 154.85707 | G2: =regional_houseprice!G2/regional_rent!G2 -> 215.14175 | H2: =regional_houseprice!H2/regional_rent!H2 -> 188.45544 | I2: =regional_houseprice!I2/regional_rent!I2 -> 167.29362 | ... AA2: =regional_houseprice!AA2/regional_rent!AA2 -> 162.03782
A3: 2006 | B3: =regional_houseprice!B3/regional_rent!B3 -> 88.244069 | C3: =regional_houseprice!C3/regional_rent!C3 -> 163.47107 | D3: =regional_houseprice!D3/regional_rent!D3 -> 196.99268 | E3: =regional_houseprice!E3/regional_rent!E3 -> 122.06012 | F3: =regional_houseprice!F3/regional_rent!F3 -> 181.86667 | G3: =regional_houseprice!G3/regional_rent!G3 -> 244.56266 | H3: =regional_houseprice!H3/regional_rent!H3 -> 216.46983 | I3: =regional_houseprice!I3/regional_rent!I3 -> 192.67698 | ... AA3: =regional_houseprice!AA3/regional_rent!AA3 -> 182.37351
A4: 2007 | B4: =regional_houseprice!B4/regional_rent!B4 -> 88.318031 | C4: =regional_houseprice!C4/regional_rent!C4 -> 156.26104 | D4: =regional_houseprice!D4/regional_rent!D4 -> 187.67356 | E4: =regional_houseprice!E4/regional_rent!E4 -> 120.72368 | F4: =regional_houseprice!F4/regional_rent!F4 -> 177.13106 | G4: =regional_houseprice!G4/regional_rent!G4 -> 229.89319 | H4: =regional_houseprice!H4/regional_rent!H4 -> 205.34512 | I4: =regional_houseprice!I4/regional_rent!I4 -> 182.8321 | ... AA4: =regional_houseprice!AA4/regional_rent!AA4 -> 171.09763
A5: 2008 | B5: =regional_houseprice!B5/regional_rent!B5 -> 95.900906 | C5: =regional_houseprice!C5/regional_rent!C5 -> 164.12365 | D5: =regional_houseprice!D5/regional_rent!D5 -> 197.79627 | E5: =regional_houseprice!E5/regional_rent!E5 -> 130.44532 | F5: =regional_houseprice!F5/regional_rent!F5 -> 190.53072 | G5: =regional_houseprice!G5/regional_rent!G5 -> 238.39037 | H5: =regional_houseprice!H5/regional_rent!H5 -> 214.50067 | I5: =regional_houseprice!I5/regional_rent!I5 -> 190.69971 | ... AA5: =regional_houseprice!AA5/regional_rent!AA5 -> 178.93848
A6: 2009 | B6: =regional_houseprice!B6/regional_rent!B6 -> 87.513829 | C6: =regional_houseprice!C6/regional_rent!C6 -> 143.71179 | D6: =regional_houseprice!D6/regional_rent!D6 -> 172.81974 | E6: =regional_houseprice!E6/regional_rent!E6 -> 116.40593 | F6: =regional_houseprice!F6/regional_rent!F6 -> 170.71461 | G6: =regional_houseprice!G6/regional_rent!G6 -> 202.47021 | H6: =regional_houseprice!H6/regional_rent!H6 -> 184.91821 | I6: =regional_houseprice!I6/regional_rent!I6 -> 165.95823 | ... AA6: =regional_houseprice!AA6/regional_rent!AA6 -> 155.42345
A7: 2010 | B7: =regional_houseprice!B7/regional_rent!B7 -> 91.546786 | C7: =regional_houseprice!C7/regional_rent!C7 -> 148.77009 | D7: =regional_houseprice!D7/regional_rent!D7 -> 177.37728 | E7: =regional_houseprice!E7/regional_rent!E7 -> 120.87767 | F7: =regional_houseprice!F7/regional_rent!F7 -> 178.62847 | G7: =regional_houseprice!G7/regional_rent!G7 -> 203.90278 | H7: =regional_houseprice!H7/regional_rent!H7 -> 187.06311 | I7: =regional_houseprice!I7/regional_rent!I7 -> 170.46734 | ... AA7: =regional_houseprice!AA7/regional_rent!AA7 -> 156.81242
A8: 2011 | B8: =regional_houseprice!B8/regional_rent!B8 -> 97.751697 | C8: =regional_houseprice!C8/regional_rent!C8 -> 151.79334 | D8: =regional_houseprice!D8/regional_rent!D8 -> 177.28729 | E8: =regional_houseprice!E8/regional_rent!E8 -> 127.32218 | F8: =regional_houseprice!F8/regional_rent!F8 -> 182.11795 | G8: =regional_houseprice!G8/regional_rent!G8 -> 213.59326 | H8: =regional_houseprice!H8/regional_rent!H8 -> 191.41597 | I8: =regional_houseprice!I8/regional_rent!I8 -> 171.61183 | ... AA8: =regional_houseprice!AA8/regional_rent!AA8 -> 173.16477
A9: 2012 | B9: =regional_houseprice!B9/regional_rent!B9 -> 105.03282 | C9: =regional_houseprice!C9/regional_rent!C9 -> 153.73982 | D9: =regional_houseprice!D9/regional_rent!D9 -> 180.178 | E9: =regional_houseprice!E9/regional_rent!E9 -> 133.17581 | F9: =regional_houseprice!F9/regional_rent!F9 -> 185.65176 | G9: =regional_houseprice!G9/regional_rent!G9 -> 231.63042 | H9: =regional_houseprice!H9/regional_rent!H9 -> 193.72735 | I9: =regional_houseprice!I9/regional_rent!I9 -> 170.79787 | ... AA9: =regional_houseprice!AA9/regional_rent!AA9 -> 198.02751
A10: 2013 | B10: =regional_houseprice!B10/regional_rent!B10 -> 115.04356 | C10: =regional_houseprice!C10/regional_rent!C10 -> 155.22667 | D10: =regional_houseprice!D10/regional_rent!D10 -> 181.41098 | E10: =regional_houseprice!E10/regional_rent!E10 -> 140.79586 | F10: =regional_houseprice!F10/regional_rent!F10 -> 193.07127 | G10: =regional_houseprice!G10/regional_rent!G10 -> 243.32644 | H10: =regional_houseprice!H10/regional_rent!H10 -> 197.21648 | I10: =regional_houseprice!I10/regional_rent!I10 -> 172.91073 | ... AA10: =regional_houseprice!AA10/regional_rent!AA10 -> 208.14704
A11: 2014 | B11: =regional_houseprice!B11/regional_rent!B11 -> 130.21703 | C11: =regional_houseprice!C11/regional_rent!C11 -> 158.88075 | D11: =regional_houseprice!D11/regional_rent!D11 -> 182.68561 | E11: =regional_houseprice!E11/regional_rent!E11 -> 148.56313 | F11: =regional_houseprice!F11/regional_rent!F11 -> 204.38014 | G11: =regional_houseprice!G11/regional_rent!G11 -> 246.45122 | H11: =regional_houseprice!H11/regional_rent!H11 -> 201.33402 | I11: =regional_houseprice!I11/regional_rent!I11 -> 179.60135 | ... AA11: =regional_houseprice!AA11/regional_rent!AA11 -> 211.03351
A12: 2015 | B12: =regional_houseprice!B12/regional_rent!B12 -> 153.21165 | C12: =regional_houseprice!C12/regional_rent!C12 -> 171.01123 | D12: =regional_houseprice!D12/regional_rent!D12 -> 196.29112 | E12: =regional_houseprice!E12/regional_rent!E12 -> 160.59099 | F12: =regional_houseprice!F12/regional_rent!F12 -> 226.83997 | G12: =regional_houseprice!G12/regional_rent!G12 -> 251.42392 | H12: =regional_houseprice!H12/regional_rent!H12 -> 209.00447 | I12: =regional_houseprice!I12/regional_rent!I12 -> 194.01714 | ... AA12: =regional_houseprice!AA12/regional_rent!AA12 -> 210.1368
A13: 2016 | B13: =regional_houseprice!B13/regional_rent!B13 -> 165.18042 | C13: =regional_houseprice!C13/regional_rent!C13 -> 189.07199 | D13: =regional_houseprice!D13/regional_rent!D13 -> 209.87709 | E13: =regional_houseprice!E13/regional_rent!E13 -> 171.13176 | F13: =regional_houseprice!F13/regional_rent!F13 -> 241.92428 | G13: =regional_houseprice!G13/regional_rent!G13 -> 251.52185 | H13: =regional_houseprice!H13/regional_rent!H13 -> 217.36631 | I13: =regional_houseprice!I13/regional_rent!I13 -> 210.21245 | ... AA13: =regional_houseprice!AA13/regional_rent!AA13 -> 199.7259
... A19: 2022 | B19: =regional_houseprice!B19/regional_rent!B19 -> 250.59744 | C19: =regional_houseprice!C19/regional_rent!C19 -> 325.44864 | D19: =regional_houseprice!D19/regional_rent!D19 -> 384.28207 | E19: =regional_houseprice!E19/regional_rent!E19 -> 264.37597 | F19: =regional_houseprice!F19/regional_rent!F19 -> 460.35379 | G19: =regional_houseprice!G19/regional_rent!G19 -> 368.66102 | H19: =regional_houseprice!H19/regional_rent!H19 -> 311.92446 | I19: =regional_houseprice!I19/regional_rent!I19 -> 306.59301 | ... AA19: =regional_houseprice!AA19/regional_rent!AA19 -> 399.9418

Sheet regional_rent_multiplier_ibbs2
A1: year | B1: TR1 | C1: TR21 | D1: TR22 | E1: TR31 | F1: TR32 | G1: TR33 | H1: TR41 | I1: TR42 | J1: TR51 | K1: TR52 | L1: TR61 | M1: TR62 | N1: TR63 | O1: TR71 | P1: TR72 | Q1: TR81 | R1: TR82 | S1: TR83 | T1: TR90 | U1: TRA1 | V1: TRA2 | W1: TRB1 | X1: TRB2 | Y1: TRC1 | Z1: TRC2 | AA1: TRC3
A2: 2005 | B2: =regional_houseprice!B2/regional_rent!B2 -> 72.344727 | C2: =regional_houseprice!C2/regional_rent!C2 -> 141.27845 | D2: =regional_houseprice!D2/regional_rent!D2 -> 171.28356 | E2: =regional_houseprice!E2/regional_rent!E2 -> 101.86069 | F2: =regional_houseprice!F2/regional_rent!F2 -> 154.85707 | G2: =regional_houseprice!G2/regional_rent!G2 -> 215.14175 | H2: =regional_houseprice!H2/regional_rent!H2 -> 188.45544 | I2: =regional_houseprice!I2/regional_rent!I2 -> 167.29362 | ... AA2: =regional_houseprice!AA2/regional_rent!AA2 -> 162.03782
A3: 2006 | B3: =regional_houseprice!B3/regional_rent!B3 -> 88.244069 | C3: =regional_houseprice!C3/regional_rent!C3 -> 163.47107 | D3: =regional_houseprice!D3/regional_rent!D3 -> 196.99268 | E3: =regional_houseprice!E3/regional_rent!E3 -> 122.06012 | F3: =regional_houseprice!F3/regional_rent!F3 -> 181.86667 | G3: =regional_houseprice!G3/regional_rent!G3 -> 244.56266 | H3: =regional_houseprice!H3/regional_rent!H3 -> 216.46983 | I3: =regional_houseprice!I3/regional_rent!I3 -> 192.67698 | ... AA3: =regional_houseprice!AA3/regional_rent!AA3 -> 182.37351
A4: 2007 | B4: =regional_houseprice!B4/regional_rent!B4 -> 88.318031 | C4: =regional_houseprice!C4/regional_rent!C4 -> 156.26104 | D4: =regional_houseprice!D4/regional_rent!D4 -> 187.67356 | E4: =regional_houseprice!E4/regional_rent!E4 -> 120.72368 | F4: =regional_houseprice!F4/regional_rent!F4 -> 177.13106 | G4: =regional_houseprice!G4/regional_rent!G4 -> 229.89319 | H4: =regional_houseprice!H4/regional_rent!H4 -> 205.34512 | I4: =regional_houseprice!I4/regional_rent!I4 -> 182.8321 | ... AA4: =regional_houseprice!AA4/regional_rent!AA4 -> 171.09763
A5: 2008 | B5: =regional_houseprice!B5/regional_rent!B5 -> 95.900906 | C5: =regional_houseprice!C5/regional_rent!C5 -> 164.12365 | D5: =regional_houseprice!D5/regional_rent!D5 -> 197.79627 | E5: =regional_houseprice!E5/regional_rent!E5 -> 130.44532 | F5: =regional_houseprice!F5/regional_rent!F5 -> 190.53072 | G5: =regional_houseprice!G5/regional_rent!G5 -> 238.39037 | H5: =regional_houseprice!H5/regional_rent!H5 -> 214.50067 | I5: =regional_houseprice!I5/regional_rent!I5 -> 190.69971 | ... AA5: =regional_houseprice!AA5/regional_rent!AA5 -> 178.93848
A6: 2009 | B6: =regional_houseprice!B6/regional_rent!B6 -> 87.513829 | C6: =regional_houseprice!C6/regional_rent!C6 -> 143.71179 | D6: =regional_houseprice!D6/regional_rent!D6 -> 172.81974 | E6: =regional_houseprice!E6/regional_rent!E6 -> 116.40593 | F6: =regional_houseprice!F6/regional_rent!F6 -> 170.71461 | G6: =regional_houseprice!G6/regional_rent!G6 -> 202.47021 | H6: =regional_houseprice!H6/regional_rent!H6 -> 184.91821 | I6: =regional_houseprice!I6/regional_rent!I6 -> 165.95823 | ... AA6: =regional_houseprice!AA6/regional_rent!AA6 -> 155.42345
A7: 2010 | B7: =regional_houseprice!B7/regional_rent!B7 -> 91.546786 | C7: =regional_houseprice!C7/regional_rent!C7 -> 148.77009 | D7: =regional_houseprice!D7/regional_rent!D7 -> 177.37728 | E7: =regional_houseprice!E7/regional_rent!E7 -> 120.87767 | F7: =regional_houseprice!F7/regional_rent!F7 -> 178.62847 | G7: =regional_houseprice!G7/regional_rent!G7 -> 203.90278 | H7: =regional_houseprice!H7/regional_rent!H7 -> 187.06311 | I7: =regional_houseprice!I7/regional_rent!I7 -> 170.46734 | ... AA7: =regional_houseprice!AA7/regional_rent!AA7 -> 156.81242
A8: 2011 | B8: =regional_houseprice!B8/regional_rent!B8 -> 97.751697 | C8: =regional_houseprice!C8/regional_rent!C8 -> 151.79334 | D8: =regional_houseprice!D8/regional_rent!D8 -> 177.28729 | E8: =regional_houseprice!E8/regional_rent!E8 -> 127.32218 | F8: =regional_houseprice!F8/regional_rent!F8 -> 182.11795 | G8: =regional_houseprice!G8/regional_rent!G8 -> 213.59326 | H8: =regional_houseprice!H8/regional_rent!H8 -> 191.41597 | I8: =regional_houseprice!I8/regional_rent!I8 -> 171.61183 | ... AA8: =regional_houseprice!AA8/regional_rent!AA8 -> 173.16477
A9: 2012 | B9: =regional_houseprice!B9/regional_rent!B9 -> 105.03282 | C9: =regional_houseprice!C9/regional_rent!C9 -> 153.73982 | D9: =regional_houseprice!D9/regional_rent!D9 -> 180.178 | E9: =regional_houseprice!E9/regional_rent!E9 -> 133.17581 | F9: =regional_houseprice!F9/regional_rent!F9 -> 185.65176 | G9: =regional_houseprice!G9/regional_rent!G9 -> 231.63042 | H9: =regional_houseprice!H9/regional_rent!H9 -> 193.72735 | I9: =regional_houseprice!I9/regional_rent!I9 -> 170.79787 | ... AA9: =regional_houseprice!AA9/regional_rent!AA9 -> 198.02751
A10: 2013 | B10: =regional_houseprice!B10/regional_rent!B10 -> 115.04356 | C10: =regional_houseprice!C10/regional_rent!C10 -> 155.22667 | D10: =regional_houseprice!D10/regional_rent!D10 -> 181.41098 | E10: =regional_houseprice!E10/regional_rent!E10 -> 140.79586 | F10: =regional_houseprice!F10/regional_rent!F10 -> 193.07127 | G10: =regional_houseprice!G10/regional_rent!G10 -> 243.32644 | H10: =regional_houseprice!H10/regional_rent!H10 -> 197.21648 | I10: =regional_houseprice!I10/regional_rent!I10 -> 172.91073 | ... AA10: =regional_houseprice!AA10/regional_rent!AA10 -> 208.14704
A11: 2014 | B11: =regional_houseprice!B11/regional_rent!B11 -> 130.21703 | C11: =regional_houseprice!C11/regional_rent!C11 -> 158.88075 | D11: =regional_houseprice!D11/regional_rent!D11 -> 182.68561 | E11: =regional_houseprice!E11/regional_rent!E11 -> 148.56313 | F11: =regional_houseprice!F11/regional_rent!F11 -> 204.38014 | G11: =regional_houseprice!G11/regional_rent!G11 -> 246.45122 | H11: =regional_houseprice!H11/regional_rent!H11 -> 201.33402 | I11: =regional_houseprice!I11/regional_rent!I11 -> 179.60135 | ... AA11: =regional_houseprice!AA11/regional_rent!AA11 -> 211.03351
A12: 2015 | B12: =regional_houseprice!B12/regional_rent!B12 -> 153.21165 | C12: =regional_houseprice!C12/regional_rent!C12 -> 171.01123 | D12: =regional_houseprice!D12/regional_rent!D12 -> 196.29112 | E12: =regional_houseprice!E12/regional_rent!E12 -> 160.59099 | F12: =regional_houseprice!F12/regional_rent!F12 -> 226.83997 | G12: =regional_houseprice!G12/regional_rent!G12 -> 251.42392 | H12: =regional_houseprice!H12/regional_rent!H12 -> 209.00447 | I12: =regional_houseprice!I12/regional_rent!I12 -> 194.01714 | ... AA12: =regional_houseprice!AA12/regional_rent!AA12 -> 210.1368
A13: 2016 | B13: =regional_houseprice!B13/regional_rent!B13 -> 165.18042 | C13: =regional_houseprice!C13/regional_rent!C13 -> 189.07199 | D13: =regional_houseprice!D13/regional_rent!D13 -> 209.87709 | E13: =regional_houseprice!E13/regional_rent!E13 -> 171.13176 | F13: =regional_houseprice!F13/regional_rent!F13 -> 241.92428 | G13: =regional_houseprice!G13/regional_rent!G13 -> 251.52185 | H13: =regional_houseprice!H13/regional_rent!H13 -> 217.36631 | I13: =regional_houseprice!I13/regional_rent!I13 -> 210.21245 | ... AA13: =regional_houseprice!AA13/regional_rent!AA13 -> 199.7259
... A19: 2022 | B19: =regional_houseprice!B19/regional_rent!B19 -> 250.59744 | C19: =regional_houseprice!C19/regional_rent!C19 -> 325.44864 | D19: =regional_houseprice!D19/regional_rent!D19 -> 384.28207 | E19: =regional_houseprice!E19/regional_rent!E19 -> 264.37597 | F19: =regional_houseprice!F19/regional_rent!F19 -> 460.35379 | G19: =regional_houseprice!G19/regional_rent!G19 -> 368.66102 | H19: =regional_houseprice!H19/regional_rent!H19 -> 311.92446 | I19: =regional_houseprice!I19/regional_rent!I19 -> 306.59301 | ... AA19: =regional_houseprice!AA19/regional_rent!AA19 -> 399.9418

Sheet regional_houseprice
A1: year | B1: TR10 (İstanbul) | C1: TR21 (Tekirdağ, Edirne, Kırklareli) | D1: TR22 (Balıkesir, Çanakkale) | E1: TR31 (İzmir) | F1: TR32 (Aydın, Denizli, Muğla) | G1: TR33 (Manisa, Afyon, Kütahya, Uşak) | H1: TR41 (Bursa, Eskişehir, Bilecik) | I1: TR42 (Kocaeli, Sakarya, Düzce, Bolu, Yalova) | J1: TR51 (Ankara) | K1: TR52 (Konya, Karaman) | L1: TR61 (Antalya, Isparta, Burdur) | M1: TR62 (Adana, Mersin) | N1: TR63 (Hatay, K.Maraş, Osmaniye) | O1: TR71 (Kırıkkale, Aksaray, Niğde, Nevşehir, Kırşehir) | P1: TR72 (Kayseri, Sivas, Yozgat) | Q1: TR81 (Zonguldak, Karabük, Bartın) | R1: TR82 (Kastamonu, Çankırı, Sinop) | S1: TR83 (Samsun, Tokat, Çorum, Amasya) | T1: TR90 (Trabzon, Ordu, Giresun, Rize, Artvin, Gümüşhane) | U1: TRA1 (Erzurum, Erzincan, Bayburt) | V1: TRA2 (Ağrı, Kars, Iğdır, Ardahan) | W1: TRB1 (Malatya, Elazığ, Bingöl, Tunceli) | X1: TRB2 (Van, Muş, Bitlis, Hakkari) | Y1: TRC1 (Gaziantep, Adıyaman, Kilis) | Z1: TRC2 (Şanlıurfa, Diyarbakır) | AA1: TRC3 (Mardin, Batman, Şırnak, Siirt)
A2: 2005 | B2: =B3/(1+regional_houseprice_growth!D2) -> 66973.92 | C2: =C3/(1+regional_houseprice_growth!E2) -> 44449.266 | D2: =D3/(1+regional_houseprice_growth!F2) -> 57071.826 | E2: =E3/(1+regional_houseprice_growth!G2) -> 60630.038 | F2: =F3/(1+regional_houseprice_growth!H2) -> 58575.504 | G2: =G3/(1+regional_houseprice_growth!I2) -> 52155.404 | H2: =H3/(1+regional_houseprice_growth!J2) -> 53334.493 | I2: =I3/(1+regional_houseprice_growth!K2) -> 54878.676 | ... O2: =O3/(1+regional_houseprice_growth!Q2) -> 52122.893 | P2: =P3/(1+regional_houseprice_growth!Q2) -> 50188.156 | Q2: =Q3/(1+regional_houseprice_growth!R2) -> 53573.41 | R2: =R3/(1+regional_houseprice_growth!R2) -> 53556.663 | S2: =S3/(1+regional_houseprice_growth!R2) -> 54480.7 | T2: =T3/(1+regional_houseprice_growth!S2) -> 62058.767 | U2: =U3/(1+regional_houseprice_growth!T2) -> 57171.072 | V2: =V3/(1+regional_houseprice_growth!T2) -> 49914.634 | W2: =W3/(1+regional_houseprice_growth!U2) -> 56074.686 | X2: =X3/(1+regional_houseprice_growth!U2) -> 47608.45 | Y2: =Y3/(1+regional_houseprice_growth!V2) -> 53367.754 | Z2: =Z3/(1+regional_houseprice_growth!V2) -> 49262.565 | AA2: =AA3/(1+regional_houseprice_growth!V2) -> 45215.594
A3: 2006 | B3: =B4/(1+regional_houseprice_growth!D3) -> 93887.92 | C3: =C4/(1+regional_houseprice_growth!E3) -> 61752.544 | D3: =D4/(1+regional_houseprice_growth!F3) -> 79190.939 | E3: =E4/(1+regional_houseprice_growth!G3) -> 84980.815 | F3: =F4/(1+regional_houseprice_growth!H3) -> 82038.392 | G3: =G4/(1+regional_houseprice_growth!I3) -> 71708.917 | H3: =H4/(1+regional_houseprice_growth!J3) -> 73386.318 | I3: =I4/(1+regional_houseprice_growth!K3) -> 75627.251 | ... O3: =O4/(1+regional_houseprice_growth!Q3) -> 71644.026 | P3: =P4/(1+regional_houseprice_growth!Q3) -> 68984.689 | Q3: =Q4/(1+regional_houseprice_growth!R3) -> 73519.646 | R3: =R4/(1+regional_houseprice_growth!R3) -> 73496.664 | S3: =S4/(1+regional_houseprice_growth!R3) -> 74764.735 | T3: =T4/(1+regional_houseprice_growth!S3) -> 85086.658 | U3: =U4/(1+regional_houseprice_growth!T3) -> 78328.793 | V3: =V4/(1+regional_houseprice_growth!T3) -> 68386.913 | W3: =W4/(1+regional_houseprice_growth!U3) -> 77000.209 | X3: =X4/(1+regional_houseprice_growth!U3) -> 65374.607 | Y3: =Y4/(1+regional_houseprice_growth!V3) -> 73645.72 | Z3: =Z4/(1+regional_houseprice_growth!V3) -> 67980.696 | AA3: =AA4/(1+regional_houseprice_growth!V3) -> 62396.011
A4: 2007 | B4: =B5/(1+regional_houseprice_growth!D4) -> 108082.12 | C4: =C5/(1+regional_houseprice_growth!E4) -> 70438.801 | D4: =D5/(1+regional_houseprice_growth!F4) -> 90377.166 | E4: =E5/(1+regional_houseprice_growth!G4) -> 98151.249 | F4: =F5/(1+regional_houseprice_growth!H4) -> 94822.88 | G4: =G5/(1+regional_houseprice_growth!I4) -> 80911.245 | H4: =H5/(1+regional_houseprice_growth!J4) -> 82915.323 | I4: =I5/(1+regional_houseprice_growth!K4) -> 85395.07 | ... O4: =O5/(1+regional_houseprice_growth!Q4) -> 80831.078 | P4: =P5/(1+regional_houseprice_growth!Q4) -> 77830.729 | Q4: =Q5/(1+regional_houseprice_growth!R4) -> 82895.536 | R4: =R5/(1+regional_houseprice_growth!R4) -> 82869.623 | S4: =S5/(1+regional_houseprice_growth!R4) -> 84299.41 | T4: =T5/(1+regional_houseprice_growth!S4) -> 95581.153 | U4: =U5/(1+regional_houseprice_growth!T4) -> 87923.684 | V4: =V5/(1+regional_houseprice_growth!T4) -> 76763.971 | W4: =W5/(1+regional_houseprice_growth!U4) -> 86987.138 | X4: =X5/(1+regional_houseprice_growth!U4) -> 73853.695 | Y4: =Y5/(1+regional_houseprice_growth!V4) -> 83827.075 | Z4: =Z5/(1+regional_houseprice_growth!V4) -> 77378.875 | AA4: =AA5/(1+regional_houseprice_growth!V4) -> 71022.12
A5: 2008 | B5: =B6/(1+regional_houseprice_growth!D5) -> 130610.43 | C5: =C6/(1+regional_houseprice_growth!E5) -> 84341.658 | D5: =D6/(1+regional_houseprice_growth!F5) -> 108855.25 | E5: =E6/(1+regional_houseprice_growth!G5) -> 119225 | F5: =F6/(1+regional_houseprice_growth!H5) -> 115868.62 | G5: =G6/(1+regional_houseprice_growth!I5) -> 96005.309 | H5: =H6/(1+regional_houseprice_growth!J5) -> 98621.225 | I5: =I6/(1+regional_houseprice_growth!K5) -> 101359.87 | ... O5: =O6/(1+regional_houseprice_growth!Q5) -> 96058.987 | P5: =P6/(1+regional_houseprice_growth!Q5) -> 92493.397 | Q5: =Q6/(1+regional_houseprice_growth!R5) -> 98345.869 | R5: =R6/(1+regional_houseprice_growth!R5) -> 98315.127 | S5: =S6/(1+regional_houseprice_growth!R5) -> 100011.4 | T5: =T6/(1+regional_houseprice_growth!S5) -> 112903.91 | U5: =U6/(1+regional_houseprice_growth!T5) -> 103786.17 | V5: =V6/(1+regional_houseprice_growth!T5) -> 90613.11 | W5: =W6/(1+regional_houseprice_growth!U5) -> 103281.88 | X5: =X6/(1+regional_houseprice_growth!U5) -> 87688.23 | Y5: =Y6/(1+regional_houseprice_growth!V5) -> 100988.48 | Z5: =Z6/(1+regional_houseprice_growth!V5) -> 93220.176 | AA5: =AA6/(1+regional_houseprice_growth!V5) -> 85562.042
A6: 2009 | B6: =B7/(1+regional_houseprice_growth!D6) -> 127750.22 | C6: =C7/(1+regional_houseprice_growth!E6) -> 80276.047 | D6: =D7/(1+regional_houseprice_growth!F6) -> 103527.4 | E6: =E7/(1+regional_houseprice_growth!G6) -> 114716.64 | F6: =F7/(1+regional_houseprice_growth!H6) -> 112620.86 | G6: =G7/(1+regional_houseprice_growth!I6) -> 88819.867 | H6: =H7/(1+regional_houseprice_growth!J6) -> 92352.255 | I6: =I7/(1+regional_houseprice_growth!K6) -> 95784.318 | ... O6: =O7/(1+regional_houseprice_growth!Q6) -> 89035.402 | P6: =P7/(1+regional_houseprice_growth!Q6) -> 85730.518 | Q6: =Q7/(1+regional_houseprice_growth!R6) -> 91240.018 | R6: =R7/(1+regional_houseprice_growth!R6) -> 91211.496 | S6: =S7/(1+regional_houseprice_growth!R6) -> 92785.209 | T6: =T7/(1+regional_houseprice_growth!S6) -> 103960.17 | U6: =U7/(1+regional_houseprice_growth!T6) -> 94512.886 | V6: =V7/(1+regional_houseprice_growth!T6) -> 82516.839 | W6: =W7/(1+regional_houseprice_growth!U6) -> 94669.665 | X6: =X7/(1+regional_houseprice_growth!U6) -> 80376.303 | Y6: =Y7/(1+regional_houseprice_growth!V6) -> 95911.026 | Z6: =Z7/(1+regional_houseprice_growth!V6) -> 88533.296 | AA6: =AA7/(1+regional_houseprice_growth!V6) -> 81260.193
A7: 2010 | B7: =B8/(1+regional_houseprice_growth!D7) -> 138332.98 | C7: =C8/(1+regional_houseprice_growth!E7) -> 86587.704 | D7: =D8/(1+regional_houseprice_growth!F7) -> 110786.82 | E7: =E8/(1+regional_houseprice_growth!G7) -> 123654.51 | F7: =F8/(1+regional_houseprice_growth!H7) -> 122670.48 | G7: =G8/(1+regional_houseprice_growth!I7) -> 93291.958 | H7: =H8/(1+regional_houseprice_growth!J7) -> 97311.829 | I7: =I8/(1+regional_houseprice_growth!K7) -> 102465.72 | ... O7: =O8/(1+regional_houseprice_growth!Q7) -> 92771.091 | P7: =P8/(1+regional_houseprice_growth!Q7) -> 89327.543 | Q7: =Q8/(1+regional_houseprice_growth!R7) -> 96448.165 | R7: =R8/(1+regional_houseprice_growth!R7) -> 96418.015 | S7: =S8/(1+regional_houseprice_growth!R7) -> 98081.559 | T7: =T8/(1+regional_houseprice_growth!S7) -> 109740.22 | U7: =U8/(1+regional_houseprice_growth!T7) -> 97958.616 | V7: =V8/(1+regional_houseprice_growth!T7) -> 85525.22 | W7: =W8/(1+regional_houseprice_growth!U7) -> 98121.732 | X7: =X8/(1+regional_houseprice_growth!U7) -> 83307.172 | Y7: =Y8/(1+regional_houseprice_growth!V7) -> 101102.03 | Z7: =Z8/(1+regional_houseprice_growth!V7) -> 93324.995 | AA7: =AA8/(1+regional_houseprice_growth!V7) -> 85658.249
A8: 2011 | B8: =B9/(1+regional_houseprice_growth!D8) -> 153200.54 | C8: =C9/(1+regional_houseprice_growth!E8) -> 92243.207 | D8: =D9/(1+regional_houseprice_growth!F8) -> 115688.9 | E8: =E9/(1+regional_houseprice_growth!G8) -> 135474.43 | F8: =F9/(1+regional_houseprice_growth!H8) -> 130459.08 | G8: =G9/(1+regional_houseprice_growth!I8) -> 102135.62 | H8: =H9/(1+regional_houseprice_growth!J8) -> 103934.18 | I8: =I9/(1+regional_houseprice_growth!K8) -> 107651.23 | ... O8: =O9/(1+regional_houseprice_growth!Q8) -> 101024.75 | P8: =P9/(1+regional_houseprice_growth!Q8) -> 97274.834 | Q8: =Q9/(1+regional_houseprice_growth!R8) -> 101806.4 | R8: =R9/(1+regional_houseprice_growth!R8) -> 101774.57 | S8: =S9/(1+regional_houseprice_growth!R8) -> 103530.53 | T8: =T9/(1+regional_houseprice_growth!S8) -> 115043.65 | U8: =U9/(1+regional_houseprice_growth!T8) -> 109444.55 | V8: =V9/(1+regional_houseprice_growth!T8) -> 95553.303 | W8: =W9/(1+regional_houseprice_growth!U8) -> 103196.99 | X8: =X9/(1+regional_houseprice_growth!U8) -> 87616.163 | Y8: =Y9/(1+regional_houseprice_growth!V8) -> 116886.73 | Z8: =Z9/(1+regional_houseprice_growth!V8) -> 107895.5 | AA8: =AA9/(1+regional_houseprice_growth!V8) -> 99031.771
A9: 2012 | B9: =B10/(1+regional_houseprice_growth!D9) -> 171300.19 | C9: =C10/(1+regional_houseprice_growth!E9) -> 97898.711 | D9: =D10/(1+regional_houseprice_growth!F9) -> 123287.11 | E9: =E10/(1+regional_houseprice_growth!G9) -> 147900.5 | F9: =F10/(1+regional_houseprice_growth!H9) -> 139221.26 | G9: =G10/(1+regional_houseprice_growth!I9) -> 116181.43 | H9: =H10/(1+regional_houseprice_growth!J9) -> 110188.63 | I9: =I10/(1+regional_houseprice_growth!K9) -> 112214.48 | ... O9: =O10/(1+regional_houseprice_growth!Q9) -> 111919.57 | P9: =P10/(1+regional_houseprice_growth!Q9) -> 107765.26 | Q9: =Q10/(1+regional_houseprice_growth!R9) -> 110490.43 | R9: =R10/(1+regional_houseprice_growth!R9) -> 110455.89 | S9: =S10/(1+regional_houseprice_growth!R9) -> 112361.63 | T9: =T10/(1+regional_houseprice_growth!S9) -> 121774.93 | U9: =U10/(1+regional_houseprice_growth!T9) -> 128314.3 | V9: =V10/(1+regional_houseprice_growth!T9) -> 112028.01 | W9: =W10/(1+regional_houseprice_growth!U9) -> 111824.94 | X9: =X10/(1+regional_houseprice_growth!U9) -> 94941.449 | Y9: =Y10/(1+regional_houseprice_growth!V9) -> 140463.89 | Z9: =Z10/(1+regional_houseprice_growth!V9) -> 129659.03 | AA9: =AA10/(1+regional_houseprice_growth!V9) -> 119007.41
A10: 2013 | B10: =B11/(1+regional_houseprice_growth!D10) -> 197480.03 | C10: =C11/(1+regional_houseprice_growth!E10) -> 104919.34 | D10: =D11/(1+regional_houseprice_growth!F10) -> 131865.73 | E10: =E11/(1+regional_houseprice_growth!G10) -> 165175.76 | F10: =F11/(1+regional_houseprice_growth!H10) -> 153500.36 | G10: =G11/(1+regional_houseprice_growth!I10) -> 129707.03 | H10: =H11/(1+regional_houseprice_growth!J10) -> 119018.44 | I10: =I11/(1+regional_houseprice_growth!K10) -> 120511.3 | ... O10: =O11/(1+regional_houseprice_growth!Q10) -> 122979.47 | P10: =P11/(1+regional_houseprice_growth!Q10) -> 118414.63 | Q10: =Q11/(1+regional_houseprice_growth!R10) -> 119728.76 | R10: =R11/(1+regional_houseprice_growth!R10) -> 119691.33 | S10: =S11/(1+regional_houseprice_growth!R10) -> 121756.42 | T10: =T11/(1+regional_houseprice_growth!S10) -> 130953.94 | U10: =U11/(1+regional_houseprice_growth!T10) -> 138815.73 | V10: =V11/(1+regional_houseprice_growth!T10) -> 121196.54 | W10: =W11/(1+regional_houseprice_growth!U10) -> 121467.94 | X10: =X11/(1+regional_houseprice_growth!U10) -> 103128.53 | Y10: =Y11/(1+regional_houseprice_growth!V10) -> 157247.62 | Z10: =Z11/(1+regional_houseprice_growth!V10) -> 145151.72 | AA10: =AA11/(1+regional_houseprice_growth!V10) -> 133227.36
A11: 2014 | B11: =B12/(1+regional_houseprice_growth!D11) -> 236588.18 | C11: =C12/(1+regional_houseprice_growth!E11) -> 114670.2 | D11: =D12/(1+regional_houseprice_growth!F11) -> 141914.98 | E11: =E12/(1+regional_houseprice_growth!G11) -> 185178.7 | F11: =F12/(1+regional_houseprice_growth!H11) -> 173296.39 | G11: =G12/(1+regional_houseprice_growth!I11) -> 140458.15 | H11: =H12/(1+regional_houseprice_growth!J11) -> 129687.79 | I11: =I12/(1+regional_houseprice_growth!K11) -> 133578.79 | ... O11: =O12/(1+regional_houseprice_growth!Q11) -> 136515.47 | P11: =P12/(1+regional_houseprice_growth!Q11) -> 131448.18 | Q11: =Q12/(1+regional_houseprice_growth!R11) -> 128412.79 | R11: =R12/(1+regional_houseprice_growth!R11) -> 128372.64 | S11: =S12/(1+regional_houseprice_growth!R11) -> 130587.52 | T11: =T12/(1+regional_houseprice_growth!S11) -> 142376.71 | U11: =U12/(1+regional_houseprice_growth!T11) -> 151942.51 | V11: =V12/(1+regional_houseprice_growth!T11) -> 132657.21 | W11: =W12/(1+regional_houseprice_growth!U11) -> 128911.65 | X11: =X12/(1+regional_houseprice_growth!U11) -> 109448.39 | Y11: =Y12/(1+regional_houseprice_growth!V11) -> 170834.46 | Z11: =Z12/(1+regional_houseprice_growth!V11) -> 157693.42 | AA11: =AA12/(1+regional_houseprice_growth!V11) -> 144738.74
A12: 2015 | B12: =B13/(1+regional_houseprice_growth!D12) -> 296381.64 | C12: =C13/(1+regional_houseprice_growth!E12) -> 132611.8 | D12: =D13/(1+regional_houseprice_growth!F12) -> 163974.3 | E12: =E13/(1+regional_houseprice_growth!G12) -> 213970.8 | F12: =F13/(1+regional_houseprice_growth!H12) -> 206397.95 | G12: =G13/(1+regional_houseprice_growth!I12) -> 154157.16 | H12: =H13/(1+regional_houseprice_growth!J12) -> 144588.09 | I12: =I13/(1+regional_houseprice_growth!K12) -> 154943.1 | ... O12: =O13/(1+regional_houseprice_growth!Q12) -> 150876.83 | P12: =P13/(1+regional_houseprice_growth!Q12) -> 145276.47 | Q12: =Q13/(1+regional_houseprice_growth!R12) -> 141531.21 | R12: =R13/(1+regional_houseprice_growth!R12) -> 141486.97 | S12: =S13/(1+regional_houseprice_growth!R12) -> 143928.11 | T12: =T13/(1+regional_houseprice_growth!S12) -> 159306.9 | U12: =U13/(1+regional_houseprice_growth!T12) -> 161787.6 | V12: =V13/(1+regional_houseprice_growth!T12) -> 141252.71 | W12: =W13/(1+regional_houseprice_growth!U12) -> 141938.16 | X12: =X13/(1+regional_houseprice_growth!U12) -> 120508.13 | Y12: =Y13/(1+regional_houseprice_growth!V12) -> 183422.26 | Z12: =Z13/(1+regional_houseprice_growth!V12) -> 169312.93 | AA12: =AA13/(1+regional_houseprice_growth!V12) -> 155403.7
A13: 2016 | B13: =B14/(1+regional_houseprice_growth!D13) -> 344216.41 | C13: =C14/(1+regional_houseprice_growth!E13) -> 159524.19 | D13: =D14/(1+regional_houseprice_growth!F13) -> 190935.7 | E13: =E14/(1+regional_houseprice_growth!G13) -> 246702.88 | F13: =F14/(1+regional_houseprice_growth!H13) -> 239174.98 | G13: =G14/(1+regional_houseprice_growth!I13) -> 168029.57 | H13: =H14/(1+regional_houseprice_growth!J13) -> 163535.38 | I13: =I14/(1+regional_houseprice_growth!K13) -> 182530.02 | ... O13: =O14/(1+regional_houseprice_growth!Q13) -> 162927.16 | P13: =P14/(1+regional_houseprice_growth!Q13) -> 156879.51 | Q13: =Q14/(1+regional_houseprice_growth!R13) -> 155943.01 | R13: =R14/(1+regional_houseprice_growth!R13) -> 155894.26 | S13: =S14/(1+regional_houseprice_growth!R13) -> 158583.98 | T13: =T14/(1+regional_houseprice_growth!S13) -> 179296.75 | U13: =U14/(1+regional_houseprice_growth!T13) -> 174914.38 | V13: =V14/(1+regional_houseprice_growth!T13) -> 152713.38 | W13: =W14/(1+regional_houseprice_growth!U13) -> 152934.56 | X13: =X14/(1+regional_houseprice_growth!U13) -> 129844.28 | Y13: =Y14/(1+regional_houseprice_growth!V13) -> 190415.48 | Z13: =Z14/(1+regional_houseprice_growth!V13) -> 175768.22 | AA13: =AA14/(1+regional_houseprice_growth!V13) -> 161328.68
... A17: 2020 | B17: =B18/(1+regional_houseprice_growth!D17) -> 461217.67 | C17: =C18/(1+regional_houseprice_growth!E17) -> 267563.81 | D17: =D18/(1+regional_houseprice_growth!F17) -> 345350.96 | E17: =E18/(1+regional_houseprice_growth!G17) -> 441276.89 | F17: =F18/(1+regional_houseprice_growth!H17) -> 429346.68 | G17: =G18/(1+regional_houseprice_growth!I17) -> 266523.68 | H17: =H18/(1+regional_houseprice_growth!J17) -> 277403.1 | I17: =I18/(1+regional_houseprice_growth!K17) -> 283958.64 | ... O17: =O18/(1+regional_houseprice_growth!Q17) -> 266097.86 | P17: =P18/(1+regional_houseprice_growth!Q17) -> 256220.64 | Q17: =Q18/(1+regional_houseprice_growth!R17) -> 269944 | R17: =R18/(1+regional_houseprice_growth!R17) -> 269859.62 | S17: =S18/(1+regional_houseprice_growth!R17) -> 274515.63 | T17: =T18/(1+regional_houseprice_growth!S17) -> 296584.16 | U17: =U18/(1+regional_houseprice_growth!T17) -> 269427.22 | V17: =V18/(1+regional_houseprice_growth!T17) -> 235230.17 | W17: =W18/(1+regional_houseprice_growth!U17) -> 288444.06 | X17: =X18/(1+regional_houseprice_growth!U17) -> 244894.36 | Y17: =Y18/(1+regional_houseprice_growth!V17) -> 306303.19 | Z17: =Z18/(1+regional_houseprice_growth!V17) -> 282741.54 | AA17: =AA18/(1+regional_houseprice_growth!V17) -> 259514.02
A18: 2021 | B18: =sahibinden_rent_price_ibbs!E2 -> 621852 | C18: =AVERAGE(sahibinden_rent_price_ibbs!E4:E6) -> 355906.67 | D18: =AVERAGE(sahibinden_rent_price_ibbs!E10:E11) -> 490942.5 | E18: =sahibinden_rent_price_ibbs!E14 -> 611908 | F18: =AVERAGE(sahibinden_rent_price_ibbs!E16:E17) -> 634122 | G18: =AVERAGE(sahibinden_rent_price_ibbs!E20:E23) -> 356867.75 | H18: =AVERAGE(sahibinden_rent_price_ibbs!E28:E30) -> 377106.33 | I18: =AVERAGE(sahibinden_rent_price_ibbs!E34:E38) -> 378749.8 | J18: =sahibinden_rent_price_ibbs!E44 -> 371250 | K18: =AVERAGE(sahibinden_rent_price_ibbs!E46:E47) -> 392565 | L18: =AVERAGE(sahibinden_rent_price_ibbs!E50:E52) -> 476742 | M18: =AVERAGE(sahibinden_rent_price_ibbs!E56:E57) -> 450666 | N18: =AVERAGE(sahibinden_rent_price_ibbs!E60:E62) -> 384110.33 | O18: =AVERAGE(sahibinden_rent_price_ibbs!E66:E70) -> 363491 | P18: =AVERAGE(sahibinden_rent_price_ibbs!E76:E78) -> 349998.67 | Q18: =AVERAGE(sahibinden_rent_price_ibbs!E82:E84) -> 363620.67 | R18: =AVERAGE(sahibinden_rent_price_ibbs!E88:E90) -> 363507 | S18: =AVERAGE(sahibinden_rent_price_ibbs!E94:E97) -> 369778.75 | T18: =AVERAGE(sahibinden_rent_price_ibbs!E102:E107) -> 394289.67 | U18: =AVERAGE(sahibinden_rent_price_ibbs!E114:E116) -> 358033 | V18: =AVERAGE(sahibinden_rent_price_ibbs!E120:E122) -> 312589.67 | W18: =AVERAGE(sahibinden_rent_price_ibbs!E126:E128) -> 384197.33 | X18: =AVERAGE(sahibinden_rent_price_ibbs!E132:E134) -> 326190.67 | Y18: =AVERAGE(sahibinden_rent_price_ibbs!E138:E140) -> 448565.33 | Z18: =AVERAGE(sahibinden_rent_price_ibbs!E144:E145) -> 414060.5 | AA18: =AVERAGE(sahibinden_rent_price_ibbs!E148:E150) -> 380045
A19: 2022 | B19: =sahibinden_rent_price_ibbs!E3 -> 2133336 | C19: =AVERAGE(sahibinden_rent_price_ibbs!E7:E9) -> 957795.33 | D19: =AVERAGE(sahibinden_rent_price_ibbs!E12:E13) -> 1485634.5 | E19: =sahibinden_rent_price_ibbs!E15 -> 1639131 | F19: =AVERAGE(sahibinden_rent_price_ibbs!E18:E19) -> 1575100.5 | G19: =AVERAGE(sahibinden_rent_price_ibbs!E24:E27) -> 870040 | H19: =AVERAGE(sahibinden_rent_price_ibbs!E31:E33) -> 956672.33 | I19: =AVERAGE(sahibinden_rent_price_ibbs!E39:E43) -> 1073320.8 | J19: =sahibinden_rent_price_ibbs!E45 -> 1032435 | K19: =AVERAGE(sahibinden_rent_price_ibbs!E48:E49) -> 1057000 | L19: =AVERAGE(sahibinden_rent_price_ibbs!E53:E55) -> 1358871.3 | M19: =AVERAGE(sahibinden_rent_price_ibbs!E58:E59) -> 1474815 | N19: =AVERAGE(sahibinden_rent_price_ibbs!E63:E65) -> 908113 | O19: =AVERAGE(sahibinden_rent_price_ibbs!E71:E75) -> 898957 | P19: =AVERAGE(sahibinden_rent_price_ibbs!E79:E81) -> 909942.67 | Q19: =AVERAGE(sahibinden_rent_price_ibbs!E85:E87) -> 909276.67 | R19: =AVERAGE(sahibinden_rent_price_ibbs!E91:E93) -> 829513 | S19: =AVERAGE(sahibinden_rent_price_ibbs!E98:E101) -> 937381 | T19: =AVERAGE(sahibinden_rent_price_ibbs!E108:E113) -> 963686.5 | U19: =AVERAGE(sahibinden_rent_price_ibbs!E117:E119) -> 769357.33 | V19: =AVERAGE(sahibinden_rent_price_ibbs!E123:E125) -> 715594.67 | W19: =AVERAGE(sahibinden_rent_price_ibbs!E129:E131) -> 858141.33 | X19: =AVERAGE(sahibinden_rent_price_ibbs!E135:E137) -> 764899.33 | Y19: =AVERAGE(sahibinden_rent_price_ibbs!E141:E143) -> 1029322 | Z19: =AVERAGE(sahibinden_rent_price_ibbs!E146:E147) -> 1165267 | AA19: =AVERAGE(sahibinden_rent_price_ibbs!E151:E153) -> 849876.33

Sheet regional_houseprice_growth
A1: source | C1: TP KFE TR | D1: TP KFE TR10 | E1: TP KFE TR21 | F1: TP KFE TR22 | G1: TP KFE TR31 | H1: TP KFE TR32 | I1: TP KFE TR33 | J1: TP KFE TR41 | K1: TP KFE TR42 | L1: TP KFE TR51 | M1: TP KFE TR52 | N1: TP KFE TR61 | O1: TP KFE TR62 | P1: TP KFE TR63 | Q1: TP KFE TR7 | R1: TP KFE TR8 | S1: TP KFE TR9 | T1: TP KFE TRA | U1: TP KFE TRB | V1: TP KFE TRC
A2: extrapolated from hbs national | B2: 2005 | C2: =turkey_rental_multiplier!G3 -> 0.38559669 | D2: =C2+(AVERAGE(D3:D15)-AVERAGE(C3:C15)) -> 0.40185792 | E2: =C2+(AVERAGE(E3:E15)-AVERAGE(C3:C15)) -> 0.38928153 | F2: =C2+(AVERAGE(F3:F15)-AVERAGE(C3:C15)) -> 0.38756624 | G2: =C2+(AVERAGE(G3:G15)-AVERAGE(C3:C15)) -> 0.40162892 | H2: =C2+(AVERAGE(H3:H15)-AVERAGE(C3:C15)) -> 0.40055802 | I2: =C2+(AVERAGE(I3:I15)-AVERAGE(C3:C15)) -> 0.37490868 | J2: =C2+(AVERAGE(J3:J15)-AVERAGE(C3:C15)) -> 0.37596354 | K2: =C2+(AVERAGE(K3:K15)-AVERAGE(C3:C15)) -> 0.37808081 | L2: =C2+(AVERAGE(L3:L15)-AVERAGE(C3:C15)) -> 0.36748321 | M2: =C2+(AVERAGE(M3:M15)-AVERAGE(C3:C15)) -> 0.38686447 | N2: =C2+(AVERAGE(N3:N15)-AVERAGE(C3:C15)) -> 0.40432026 | O2: =C2+(AVERAGE(O3:O15)-AVERAGE(C3:C15)) -> 0.3915796 | P2: =C2+(AVERAGE(P3:P15)-AVERAGE(C3:C15)) -> 0.36420895 | Q2: =C2+(AVERAGE(Q3:Q15)-AVERAGE(C3:C15)) -> 0.37452128 | R2: =C2+(AVERAGE(R3:R15)-AVERAGE(C3:C15)) -> 0.37231598 | S2: =C2+(AVERAGE(S3:S15)-AVERAGE(C3:C15)) -> 0.37106588 | T2: =C2+(AVERAGE(T3:T15)-AVERAGE(C3:C15)) -> 0.3700774 | U2: =C2+(AVERAGE(U3:U15)-AVERAGE(C3:C15)) -> 0.37317235 | V2: =C2+(AVERAGE(V3:V15)-AVERAGE(C3:C15)) -> 0.37996663
A3: extrapolated from hbs national | B3: 2006 | C3: =turkey_rental_multiplier!G4 -> 0.1387547 | D3: =C3+(AVERAGE(D4:D16)-AVERAGE(C4:C16)) -> 0.15118235 | E3: =C3+(AVERAGE(E4:E16)-AVERAGE(C4:C16)) -> 0.14066233 | F3: =C3+(AVERAGE(F4:F16)-AVERAGE(C4:C16)) -> 0.1412564 | G3: =C3+(AVERAGE(G4:G16)-AVERAGE(C4:C16)) -> 0.15498127 | H3: =C3+(AVERAGE(H4:H16)-AVERAGE(C4:C16)) -> 0.15583543 | I3: =C3+(AVERAGE(I4:I16)-AVERAGE(C4:C16)) -> 0.12832892 | J3: =C3+(AVERAGE(J4:J16)-AVERAGE(C4:C16)) -> 0.12984715 | K3: =C3+(AVERAGE(K4:K16)-AVERAGE(C4:C16)) -> 0.1291574 | L3: =C3+(AVERAGE(L4:L16)-AVERAGE(C4:C16)) -> 0.1215532 | M3: =C3+(AVERAGE(M4:M16)-AVERAGE(C4:C16)) -> 0.13995976 | N3: =C3+(AVERAGE(N4:N16)-AVERAGE(C4:C16)) -> 0.16290845 | O3: =C3+(AVERAGE(O4:O16)-AVERAGE(C4:C16)) -> 0.14369094 | P3: =C3+(AVERAGE(P4:P16)-AVERAGE(C4:C16)) -> 0.12221639 | Q3: =C3+(AVERAGE(Q4:Q16)-AVERAGE(C4:C16)) -> 0.12823194 | R3: =C3+(AVERAGE(R4:R16)-AVERAGE(C4:C16)) -> 0.12752903 | S3: =C3+(AVERAGE(S4:S16)-AVERAGE(C4:C16)) -> 0.1233389 | T3: =C3+(AVERAGE(T4:T16)-AVERAGE(C4:C16)) -> 0.12249506 | U3: =C3+(AVERAGE(U4:U16)-AVERAGE(C4:C16)) -> 0.12970003 | V3: =C3+(AVERAGE(V4:V16)-AVERAGE(C4:C16)) -> 0.13824775
A4: extrapolated from hbs national | B4: 2007 | C4: =turkey_rental_multiplier!G5 -> 0.19879298 | D4: =C4+(AVERAGE(D5:D17)-AVERAGE(C5:C17)) -> 0.20843701 | E4: =C4+(AVERAGE(E5:E17)-AVERAGE(C5:C17)) -> 0.19737498 | F4: =C4+(AVERAGE(F5:F17)-AVERAGE(C5:C17)) -> 0.20445523 | G4: =C4+(AVERAGE(G5:G17)-AVERAGE(C5:C17)) -> 0.21470691 | H4: =C4+(AVERAGE(H5:H17)-AVERAGE(C5:C17)) -> 0.22194795 | I4: =C4+(AVERAGE(I5:I17)-AVERAGE(C5:C17)) -> 0.18655088 | J4: =C4+(AVERAGE(J5:J17)-AVERAGE(C5:C17)) -> 0.18942099 | K4: =C4+(AVERAGE(K5:K17)-AVERAGE(C5:C17)) -> 0.1869522 | L4: =C4+(AVERAGE(L5:L17)-AVERAGE(C5:C17)) -> 0.18029959 | M4: =C4+(AVERAGE(M5:M17)-AVERAGE(C5:C17)) -> 0.20130338 | N4: =C4+(AVERAGE(N5:N17)-AVERAGE(C5:C17)) -> 0.22925136 | O4: =C4+(AVERAGE(O5:O17)-AVERAGE(C5:C17)) -> 0.20588261 | P4: =C4+(AVERAGE(P5:P17)-AVERAGE(C5:C17)) -> 0.18670725 | Q4: =C4+(AVERAGE(Q5:Q17)-AVERAGE(C5:C17)) -> 0.18839176 | R4: =C4+(AVERAGE(R5:R17)-AVERAGE(C5:C17)) -> 0.18638317 | S4: =C4+(AVERAGE(S5:S17)-AVERAGE(C5:C17)) -> 0.18123615 | T4: =C4+(AVERAGE(T5:T17)-AVERAGE(C5:C17)) -> 0.18041196 | U4: =C4+(AVERAGE(U5:U17)-AVERAGE(C5:C17)) -> 0.18732354 | V4: =C4+(AVERAGE(V5:V17)-AVERAGE(C5:C17)) -> 0.20472386
A5: extrapolated from hbs national | B5: 2008 | C5: =turkey_rental_multiplier!G6 -> -0.047355505 | D5: =C5+(AVERAGE(D6:D18)-AVERAGE(C6:C18)) -> -0.021898753 | E5: =C5+(AVERAGE(E6:E18)-AVERAGE(C6:C18)) -> -0.048204057 | F5: =C5+(AVERAGE(F6:F18)-AVERAGE(C6:C18)) -> -0.048944337 | G5: =C5+(AVERAGE(G6:G18)-AVERAGE(C6:C18)) -> -0.037813882 | H5: =C5+(AVERAGE(H6:H18)-AVERAGE(C6:C18)) -> -0.028029698 | I5: =C5+(AVERAGE(I6:I18)-AVERAGE(C6:C18)) -> -0.07484421 | J5: =C5+(AVERAGE(J6:J18)-AVERAGE(C6:C18)) -> -0.063566136 | K5: =C5+(AVERAGE(K6:K18)-AVERAGE(C6:C18)) -> -0.055007456 | L5: =C5+(AVERAGE(L6:L18)-AVERAGE(C6:C18)) -> -0.056271164 | M5: =C5+(AVERAGE(M6:M18)-AVERAGE(C6:C18)) -> -0.050457379 | N5: =C5+(AVERAGE(N6:N18)-AVERAGE(C6:C18)) -> -0.002249131 | O5: =C5+(AVERAGE(O6:O18)-AVERAGE(C6:C18)) -> -0.0306751 | P5: =C5+(AVERAGE(P6:P18)-AVERAGE(C6:C18)) -> -0.073602877 | Q5: =C5+(AVERAGE(Q6:Q18)-AVERAGE(C6:C18)) -> -0.073117422 | R5: =C5+(AVERAGE(R6:R18)-AVERAGE(C6:C18)) -> -0.072253685 | S5: =C5+(AVERAGE(S6:S18)-AVERAGE(C6:C18)) -> -0.079215549 | T5: =C5+(AVERAGE(T6:T18)-AVERAGE(C6:C18)) -> -0.089349879 | U5: =C5+(AVERAGE(U6:U18)-AVERAGE(C6:C18)) -> -0.083385506 | V5: =C5+(AVERAGE(V6:V18)-AVERAGE(C6:C18)) -> -0.050277537
A6: extrapolated from hbs national | B6: 2009 | C6: =turkey_rental_multiplier!G7 -> 0.067783924 | D6: =C6+(AVERAGE(D7:D19)-AVERAGE(C7:C19)) -> 0.082839443 | E6: =C6+(AVERAGE(E7:E19)-AVERAGE(C7:C19)) -> 0.078624407 | F6: =C6+(AVERAGE(F7:F19)-AVERAGE(C7:C19)) -> 0.070120789 | G6: =C6+(AVERAGE(G7:G19)-AVERAGE(C7:C19)) -> 0.077912618 | H6: =C6+(AVERAGE(H7:H19)-AVERAGE(C7:C19)) -> 0.089234072 | I6: =C6+(AVERAGE(I7:I19)-AVERAGE(C7:C19)) -> 0.050350117 | J6: =C6+(AVERAGE(J7:J19)-AVERAGE(C7:C19)) -> 0.053702801 | K6: =C6+(AVERAGE(K7:K19)-AVERAGE(C7:C19)) -> 0.069754638 | L6: =C6+(AVERAGE(L7:L19)-AVERAGE(C7:C19)) -> 0.066785543 | M6: =C6+(AVERAGE(M7:M19)-AVERAGE(C7:C19)) -> 0.070809161 | N6: =C6+(AVERAGE(N7:N19)-AVERAGE(C7:C19)) -> 0.11444189 | O6: =C6+(AVERAGE(O7:O19)-AVERAGE(C7:C19)) -> 0.082748354 | P6: =C6+(AVERAGE(P7:P19)-AVERAGE(C7:C19)) -> 0.047873399 | Q6: =C6+(AVERAGE(Q7:Q19)-AVERAGE(C7:C19)) -> 0.041957346 | R6: =C6+(AVERAGE(R7:R19)-AVERAGE(C7:C19)) -> 0.057081828 | S6: =C6+(AVERAGE(S7:S19)-AVERAGE(C7:C19)) -> 0.055598694 | T6: =C6+(AVERAGE(T7:T19)-AVERAGE(C7:C19)) -> 0.036457783 | U6: =C6+(AVERAGE(U7:U19)-AVERAGE(C7:C19)) -> 0.036464339 | V6: =C6+(AVERAGE(V7:V19)-AVERAGE(C7:C19)) -> 0.054123131
A7: evds | B7: 2010 | C7: =(house_price_index_evds!C8-house_price_index_evds!C7)/house_price_index_evds!C7 -> 0.087234043 | D7: =(house_price_index_evds!D8-house_price_index_evds!D7)/house_price_index_evds!D7 -> 0.10747664 | E7: =(house_price_index_evds!G8-house_price_index_evds!G7)/house_price_index_evds!G7 -> 0.065315315 | F7: =(house_price_index_evds!H8-house_price_index_evds!H7)/house_price_index_evds!H7 -> 0.044247788 | G7: =(house_price_index_evds!F8-house_price_index_evds!F7)/house_price_index_evds!F7 -> 0.095588235 | H7: =(house_price_index_evds!I8-house_price_index_evds!I7)/house_price_index_evds!I7 -> 0.063492063 | I7: =(house_price_index_evds!J8-house_price_index_evds!J7)/house_price_index_evds!J7 -> 0.094795539 | J7: =(house_price_index_evds!K8-house_price_index_evds!K7)/house_price_index_evds!K7 -> 0.06805293 | K7: =(house_price_index_evds!L8-house_price_index_evds!L7)/house_price_index_evds!L7 -> 0.050607287 | L7: =(house_price_index_evds!E8-house_price_index_evds!E7)/house_price_index_evds!E7 -> 0.078393881 | M7: =(house_price_index_evds!M8-house_price_index_evds!M7)/house_price_index_evds!M7 -> 0.081677704 | N7: =(house_price_index_evds!N8-house_price_index_evds!N7)/house_price_index_evds!N7 -> 0.091743119 | O7: =(house_price_index_evds!O8-house_price_index_evds!O7)/house_price_index_evds!O7 -> 0.10798122 | P7: =(house_price_index_evds!P8-house_price_index_evds!P7)/house_price_index_evds!P7 -> 0.071684588 | Q7: =(house_price_index_evds!Q8-house_price_index_evds!Q7)/house_price_index_evds!Q7 -> 0.088967972 | R7: =(house_price_index_evds!R8-house_price_index_evds!R7)/house_price_index_evds!R7 -> 0.055555556 | S7: =(house_price_index_evds!S8-house_price_index_evds!S7)/house_price_index_evds!S7 -> 0.048327138 | T7: =(house_price_index_evds!T8-house_price_index_evds!T7)/house_price_index_evds!T7 -> 0.11725293 | ... V7: =(house_price_index_evds!V8-house_price_index_evds!V7)/house_price_index_evds!V7 -> 0.15612648
A8: evds | B8: 2011 | C8: =(house_price_index_evds!C9-house_price_index_evds!C8)/house_price_index_evds!C8 -> 0.10958904 | D8: =(house_price_index_evds!D9-house_price_index_evds!D8)/house_price_index_evds!D8 -> 0.11814346 | E8: =(house_price_index_evds!G9-house_price_index_evds!G8)/house_price_index_evds!G8 -> 0.061310782 | F8: =(house_price_index_evds!H9-house_price_index_evds!H8)/house_price_index_evds!H8 -> 0.065677966 | G8: =(house_price_index_evds!F9-house_price_index_evds!F8)/house_price_index_evds!F8 -> 0.091722595 | H8: =(house_price_index_evds!I9-house_price_index_evds!I8)/house_price_index_evds!I8 -> 0.067164179 | I8: =(house_price_index_evds!J9-house_price_index_evds!J8)/house_price_index_evds!J8 -> 0.13752122 | J8: =(house_price_index_evds!K9-house_price_index_evds!K8)/house_price_index_evds!K8 -> 0.060176991 | K8: =(house_price_index_evds!L9-house_price_index_evds!L8)/house_price_index_evds!L8 -> 0.04238921 | L8: =(house_price_index_evds!E9-house_price_index_evds!E8)/house_price_index_evds!E8 -> 0.088652482 | M8: =(house_price_index_evds!M9-house_price_index_evds!M8)/house_price_index_evds!M8 -> 0.13061224 | N8: =(house_price_index_evds!N9-house_price_index_evds!N8)/house_price_index_evds!N8 -> 0.095238095 | O8: =(house_price_index_evds!O9-house_price_index_evds!O8)/house_price_index_evds!O8 -> 0.10381356 | P8: =(house_price_index_evds!P9-house_price_index_evds!P8)/house_price_index_evds!P8 -> 0.073578595 | Q8: =(house_price_index_evds!Q9-house_price_index_evds!Q8)/house_price_index_evds!Q8 -> 0.10784314 | R8: =(house_price_index_evds!R9-house_price_index_evds!R8)/house_price_index_evds!R8 -> 0.085299456 | S8: =(house_price_index_evds!S9-house_price_index_evds!S8)/house_price_index_evds!S8 -> 0.058510638 | T8: =(house_price_index_evds!T9-house_price_index_evds!T8)/house_price_index_evds!T8 -> 0.17241379 | ... V8: =(house_price_index_evds!V9-house_price_index_evds!V8)/house_price_index_evds!V8 -> 0.2017094
A9: evds | B9: 2012 | C9: =(house_price_index_evds!C10-house_price_index_evds!C9)/house_price_index_evds!C9 -> 0.11287478 | D9: =(house_price_index_evds!D10-house_price_index_evds!D9)/house_price_index_evds!D9 -> 0.15283019 | E9: =(house_price_index_evds!G10-house_price_index_evds!G9)/house_price_index_evds!G9 -> 0.071713147 | F9: =(house_price_index_evds!H10-house_price_index_evds!H9)/house_price_index_evds!H9 -> 0.069582505 | G9: =(house_price_index_evds!F10-house_price_index_evds!F9)/house_price_index_evds!F9 -> 0.11680328 | H9: =(house_price_index_evds!I10-house_price_index_evds!I9)/house_price_index_evds!I9 -> 0.1025641 | I9: =(house_price_index_evds!J10-house_price_index_evds!J9)/house_price_index_evds!J9 -> 0.11641791 | J9: =(house_price_index_evds!K10-house_price_index_evds!K9)/house_price_index_evds!K9 -> 0.080133556 | K9: =(house_price_index_evds!L10-house_price_index_evds!L9)/house_price_index_evds!L9 -> 0.073937153 | L9: =(house_price_index_evds!E10-house_price_index_evds!E9)/house_price_index_evds!E9 -> 0.094462541 | M9: =(house_price_index_evds!M10-house_price_index_evds!M9)/house_price_index_evds!M9 -> 0.10649819 | N9: =(house_price_index_evds!N10-house_price_index_evds!N9)/house_price_index_evds!N9 -> 0.11253197 | O9: =(house_price_index_evds!O10-house_price_index_evds!O9)/house_price_index_evds!O9 -> 0.10364683 | P9: =(house_price_index_evds!P10-house_price_index_evds!P9)/house_price_index_evds!P9 -> 0.065420561 | Q9: =(house_price_index_evds!Q10-house_price_index_evds!Q9)/house_price_index_evds!Q9 -> 0.098820059 | R9: =(house_price_index_evds!R10-house_price_index_evds!R9)/house_price_index_evds!R9 -> 0.08361204 | S9: =(house_price_index_evds!S10-house_price_index_evds!S9)/house_price_index_evds!S9 -> 0.075376884 | T9: =(house_price_index_evds!T10-house_price_index_evds!T9)/house_price_index_evds!T9 -> 0.081841432 | ... V9: =(house_price_index_evds!V10-house_price_index_evds!V9)/house_price_index_evds!V9 -> 0.11948791
A10: evds | B10: 2013 | C10: =(house_price_index_evds!C11-house_price_index_evds!C10)/house_price_index_evds!C10 -> 0.1251981 | D10: =(house_price_index_evds!D11-house_price_index_evds!D10)/house_price_index_evds!D10 -> 0.19803601 | E10: =(house_price_index_evds!G11-house_price_index_evds!G10)/house_price_index_evds!G10 -> 0.092936803 | F10: =(house_price_index_evds!H11-house_price_index_evds!H10)/house_price_index_evds!H10 -> 0.076208178 | G10: =(house_price_index_evds!F11-house_price_index_evds!F10)/house_price_index_evds!F10 -> 0.12110092 | H10: =(house_price_index_evds!I11-house_price_index_evds!I10)/house_price_index_evds!I10 -> 0.12896406 | I10: =(house_price_index_evds!J11-house_price_index_evds!J10)/house_price_index_evds!J10 -> 0.082887701 | J10: =(house_price_index_evds!K11-house_price_index_evds!K10)/house_price_index_evds!K10 -> 0.089644513 | K10: =(house_price_index_evds!L11-house_price_index_evds!L10)/house_price_index_evds!L10 -> 0.10843373 | L10: =(house_price_index_evds!E11-house_price_index_evds!E10)/house_price_index_evds!E10 -> 0.09375 | M10: =(house_price_index_evds!M11-house_price_index_evds!M10)/house_price_index_evds!M10 -> 0.1141925 | N10: =(house_price_index_evds!N11-house_price_index_evds!N10)/house_price_index_evds!N10 -> 0.14712644 | O10: =(house_price_index_evds!O11-house_price_index_evds!O10)/house_price_index_evds!O10 -> 0.14086957 | P10: =(house_price_index_evds!P11-house_price_index_evds!P10)/house_price_index_evds!P10 -> 0.11842105 | Q10: =(house_price_index_evds!Q11-house_price_index_evds!Q10)/house_price_index_evds!Q10 -> 0.11006711 | R10: =(house_price_index_evds!R11-house_price_index_evds!R10)/house_price_index_evds!R10 -> 0.072530864 | S10: =(house_price_index_evds!S11-house_price_index_evds!S10)/house_price_index_evds!S10 -> 0.087227414 | T10: =(house_price_index_evds!T11-house_price_index_evds!T10)/house_price_index_evds!T10 -> 0.094562648 | ... V10: =(house_price_index_evds!V11-house_price_index_evds!V10)/house_price_index_evds!V10 -> 0.086404066
A11: evds | B11: 2014 | C11: =(house_price_index_evds!C12-house_price_index_evds!C11)/house_price_index_evds!C11 -> 0.15774648 | D11: =(house_price_index_evds!D12-house_price_index_evds!D11)/house_price_index_evds!D11 -> 0.25273224 | E11: =(house_price_index_evds!G12-house_price_index_evds!G11)/house_price_index_evds!G11 -> 0.15646259 | F11: =(house_price_index_evds!H12-house_price_index_evds!H11)/house_price_index_evds!H11 -> 0.15544041 | G11: =(house_price_index_evds!F12-house_price_index_evds!F11)/house_price_index_evds!F11 -> 0.15548282 | H11: =(house_price_index_evds!I12-house_price_index_evds!I11)/house_price_index_evds!I11 -> 0.19101124 | I11: =(house_price_index_evds!J12-house_price_index_evds!J11)/house_price_index_evds!J11 -> 0.097530864 | J11: =(house_price_index_evds!K12-house_price_index_evds!K11)/house_price_index_evds!K11 -> 0.11489362 | K11: =(house_price_index_evds!L12-house_price_index_evds!L11)/house_price_index_evds!L11 -> 0.15993789 | L11: =(house_price_index_evds!E12-house_price_index_evds!E11)/house_price_index_evds!E11 -> 0.10884354 | M11: =(house_price_index_evds!M12-house_price_index_evds!M11)/house_price_index_evds!M11 -> 0.12884334 | N11: =(house_price_index_evds!N12-house_price_index_evds!N11)/house_price_index_evds!N11 -> 0.17034068 | O11: =(house_price_index_evds!O12-house_price_index_evds!O11)/house_price_index_evds!O11 -> 0.16768293 | P11: =(house_price_index_evds!P12-house_price_index_evds!P11)/house_price_index_evds!P11 -> 0.11633987 | Q11: =(house_price_index_evds!Q12-house_price_index_evds!Q11)/house_price_index_evds!Q11 -> 0.10519952 | R11: =(house_price_index_evds!R12-house_price_index_evds!R11)/house_price_index_evds!R11 -> 0.10215827 | S11: =(house_price_index_evds!S12-house_price_index_evds!S11)/house_price_index_evds!S11 -> 0.11891117 | T11: =(house_price_index_evds!T12-house_price_index_evds!T11)/house_price_index_evds!T11 -> 0.064794816 | ... V11: =(house_price_index_evds!V12-house_price_index_evds!V11)/house_price_index_evds!V11 -> 0.073684211
